

fun main() {
    try {

    }
    catch(e: Exception) {
        println("Ошибка.Введите число")
    }
}

